Workbook

Sheet Read me
A1: Panoptic SDG database: department mapping
A2: Consolidated 1 October 2026 as the clean source for the gigamap 3D dashboard.
A4: Basis | B4: The department workbook's 'Panoptic to SDG alignment' sheet, columns B (primary) and C (secondary): 66 target links to 35 targets across 12 SDGs.
A5: Removed | B5: The ten suggested targets, the system map v4 SDG comparison and the AU Agenda 2063 links. They stay in the comparison workbook if needed later.
A6: Prescripts | B6: The Sep 26 and 2024 prescript columns are merged into one de-duplicated list per sub-principle; acronyms MSDG, SDIP and UID confirmed by the department.
A7: Text | B7: Criterion and question wording follow the department workbook; spelling differences with the system map are resolved in its favour. Target and indicator text comes from the UNSD framework (after the 2026 refinement).
A8: Keys | B8: Sub-principle ID (PP1.1); Link ID = sub-principle|target (PP1.1|9.1); SDG number; target code; indicator code.
A9: Sheets | B9: Principles, Sub-principles, Target links (the core table), Indicator links, Projects, Project scores, SDG matrix, SDG goals, Coverage summary, SDG target coverage, Cleanup log.
A10: Formulas | B10: Counts, SDG lists and the matrix are formulas over 'Target links', so edits there flow through.
A11: Maintenance | B11: Edit this workbook only, mainly 'Target links' and 'Sub-principles'. Then run build.py, which checks the data, writes panoptic_dashboard_data.json and rebuilds the dashboard page.
A12: For the dashboard | B12: Principles → sub-principles (weights) → target links (primary/secondary) → indicators; SDG colours in 'SDG goals'.
A13: Scoring | B13: Add a project on 'Projects' (new ID), then one row per evaluator and sub-principle on 'Project scores' (score 1–5 in steps of 0.5). Score = Σ(score ÷ 5 × weight) ÷ Σ weight. 80–100% bankable portfolio; 50–79% return to step 2; below 50% rework.
A14: Coverage and gaps | B14: 'SDG target coverage' lists all 169 SDG targets with the sub-principles and principles that link to each, and flags gaps. 'Coverage summary' rolls this up per SDG. Both are formulas over 'Target links'; the amber columns are for the team's gap discussion and do not change the mapping until a link is added on 'Target links'.

Sheet Principles
A1: Principle | B1: Name | C1: Short name | D1: Sub-principles | E1: Weight | F1: SDGs | G1: Primary SDGs | H1: Target links | I1: Indicator links
A2: PP1 | B2: Innovation supporting equitable development | C2: Innovation | D2: =COUNTIF('Sub-principles'!$B$2:$B$11,A2) -> 2 | E2: =SUMIF('Sub-principles'!$B$2:$B$11,A2,'Sub-principles'!$E$2:$E$11) -> 16 | F2: =_xlfn.TEXTJOIN(", ",TRUE(),IF(COUNTIFS(tl_principle,$A2,tl_sdg,1)>0,"1",""),IF(COUNTIFS(tl_principle,$A2,tl_sdg,2)>0,"2",""),IF(COUNTIFS(tl_principle,$A2,tl_sdg,3)>0,"3",""),IF(COUNTIFS(tl_principle,$A2,tl_sdg,4)>0,"4",""),IF(COUNTIFS(tl_principle,$A2,tl_sdg,5)>0,"5",""),IF(COUNTIFS(tl_principle,$A2,tl_sdg,6)>0,"6",""),IF(COUNTIFS(tl_principle,$A2,tl_sdg,7)>0,"7",""),IF(COUNTIFS(tl_principle,$A2,tl_sdg,8)>0,"8",""),IF(COUNTIFS(tl_principle,$A2,tl_sdg,9)>0,"9",""),IF(COUNTIFS(tl_principle,$A2,tl_sdg,10)>0,"10",""),IF(COUNTIFS(tl_principle,$A2,tl_sdg,11)>0,"11",""),IF(COUNTIFS(tl_principle,$A2,tl_sdg,12)>0,"12",""),IF(COUNTIFS(tl_principle,$A2,tl_sdg,13)>0,"13",""),IF(COUNTIFS(tl_principle,$A2,tl_sdg,14)>0,"14",""),IF(COUNTIFS(tl_principle,$A2,tl_sdg,15)>0,"15",""),IF(COUNTIFS(tl_principle,$A2,tl_sdg,16)>0,"16",""),IF(COUNTIFS(tl_principle,$A2,tl_sdg,17)>0,"17","")) -> 8, 9, 11, 12, 16, 17 | G2: =_xlfn.TEXTJOIN(", ",TRUE(),IF(COUNTIFS(tl_principle,$A2,tl_sdg,1,tl_align,"Primary")>0,"1",""),IF(COUNTIFS(tl_principle,$A2,tl_sdg,2,tl_align,"Primary")>0,"2",""),IF(COUNTIFS(tl_principle,$A2,tl_sdg,3,tl_align,"Primary")>0,"3",""),IF(COUNTIFS(tl_principle,$A2,tl_sdg,4,tl_align,"Primary")>0,"4",""),IF(COUNTIFS(tl_principle,$A2,tl_sdg,5,tl_align,"Primary")>0,"5",""),IF(COUNTIFS(tl_principle,$A2,tl_sdg,6,tl_align,"Primary")>0,"6",""),IF(COUNTIFS(tl_principle,$A2,tl_sdg,7,tl_align,"Primary")>0,"7",""),IF(COUNTIFS(tl_principle,$A2,tl_sdg,8,tl_align,"Primary")>0,"8",""),IF(COUNTIFS(tl_principle,$A2,tl_sdg,9,tl_align,"Primary")>0,"9",""),IF(COUNTIFS(tl_principle,$A2,tl_sdg,10,tl_align,"Primary")>0,"10",""),IF(COUNTIFS(tl_principle,$A2,tl_sdg,11,tl_align,"Primary")>0,"11",""),IF(COUNTIFS(tl_principle,$A2,tl_sdg,12,tl_align,"Primary")>0,"12",""),IF(COUNTIFS(tl_principle,$A2,tl_sdg,13,tl_align,"Primary")>0,"13",""),IF(COUNTIFS(tl_principle,$A2,tl_sdg,14,tl_align,"Primary")>0,"14",""),IF(COUNTIFS(tl_principle,$A2,tl_sdg,15,tl_align,"Primary")>0,"15",""),IF(COUNTIFS(tl_principle,$A2,tl_sdg,16,tl_align,"Primary")>0,"16",""),IF(COUNTIFS(tl_principle,$A2,tl_sdg,17,tl_align,"Primary")>0,"17","")) -> 9 | H2: =COUNTIF(tl_principle,A2) -> 12 | I2: =SUMIF('Sub-principles'!$B$2:$B$11,A2,'Sub-principles'!$M$2:$M$11) -> 19
A3: PP2 | B3: Resilient, sustainable and regenerative systems | C3: Resilience | D3: =COUNTIF('Sub-principles'!$B$2:$B$11,A3) -> 3 | E3: =SUMIF('Sub-principles'!$B$2:$B$11,A3,'Sub-principles'!$E$2:$E$11) -> 24 | F3: =_xlfn.TEXTJOIN(", ",TRUE(),IF(COUNTIFS(tl_principle,$A3,tl_sdg,1)>0,"1",""),IF(COUNTIFS(tl_principle,$A3,tl_sdg,2)>0,"2",""),IF(COUNTIFS(tl_principle,$A3,tl_sdg,3)>0,"3",""),IF(COUNTIFS(tl_principle,$A3,tl_sdg,4)>0,"4",""),IF(COUNTIFS(tl_principle,$A3,tl_sdg,5)>0,"5",""),IF(COUNTIFS(tl_principle,$A3,tl_sdg,6)>0,"6",""),IF(COUNTIFS(tl_principle,$A3,tl_sdg,7)>0,"7",""),IF(COUNTIFS(tl_principle,$A3,tl_sdg,8)>0,"8",""),IF(COUNTIFS(tl_principle,$A3,tl_sdg,9)>0,"9",""),IF(COUNTIFS(tl_principle,$A3,tl_sdg,10)>0,"10",""),IF(COUNTIFS(tl_principle,$A3,tl_sdg,11)>0,"11",""),IF(COUNTIFS(tl_principle,$A3,tl_sdg,12)>0,"12",""),IF(COUNTIFS(tl_principle,$A3,tl_sdg,13)>0,"13",""),IF(COUNTIFS(tl_principle,$A3,tl_sdg,14)>0,"14",""),IF(COUNTIFS(tl_principle,$A3,tl_sdg,15)>0,"15",""),IF(COUNTIFS(tl_principle,$A3,tl_sdg,16)>0,"16",""),IF(COUNTIFS(tl_principle,$A3,tl_sdg,17)>0,"17","")) -> 6, 7, 8, 9, 11, 12, 13, 17 | G3: =_xlfn.TEXTJOIN(", ",TRUE(),IF(COUNTIFS(tl_principle,$A3,tl_sdg,1,tl_align,"Primary")>0,"1",""),IF(COUNTIFS(tl_principle,$A3,tl_sdg,2,tl_align,"Primary")>0,"2",""),IF(COUNTIFS(tl_principle,$A3,tl_sdg,3,tl_align,"Primary")>0,"3",""),IF(COUNTIFS(tl_principle,$A3,tl_sdg,4,tl_align,"Primary")>0,"4",""),IF(COUNTIFS(tl_principle,$A3,tl_sdg,5,tl_align,"Primary")>0,"5",""),IF(COUNTIFS(tl_principle,$A3,tl_sdg,6,tl_align,"Primary")>0,"6",""),IF(COUNTIFS(tl_principle,$A3,tl_sdg,7,tl_align,"Primary")>0,"7",""),IF(COUNTIFS(tl_principle,$A3,tl_sdg,8,tl_align,"Primary")>0,"8",""),IF(COUNTIFS(tl_principle,$A3,tl_sdg,9,tl_align,"Primary")>0,"9",""),IF(COUNTIFS(tl_principle,$A3,tl_sdg,10,tl_align,"Primary")>0,"10",""),IF(COUNTIFS(tl_principle,$A3,tl_sdg,11,tl_align,"Primary")>0,"11",""),IF(COUNTIFS(tl_principle,$A3,tl_sdg,12,tl_align,"Primary")>0,"12",""),IF(COUNTIFS(tl_principle,$A3,tl_sdg,13,tl_align,"Primary")>0,"13",""),IF(COUNTIFS(tl_principle,$A3,tl_sdg,14,tl_align,"Primary")>0,"14",""),IF(COUNTIFS(tl_principle,$A3,tl_sdg,15,tl_align,"Primary")>0,"15",""),IF(COUNTIFS(tl_principle,$A3,tl_sdg,16,tl_align,"Primary")>0,"16",""),IF(COUNTIFS(tl_principle,$A3,tl_sdg,17,tl_align,"Primary")>0,"17","")) -> 9, 11, 12, 13 | H3: =COUNTIF(tl_principle,A3) -> 23 | I3: =SUMIF('Sub-principles'!$B$2:$B$11,A3,'Sub-principles'!$M$2:$M$11) -> 39
A4: PP3 | B4: Stakeholder value, trust and spatial justice | C4: Stakeholder value | D4: =COUNTIF('Sub-principles'!$B$2:$B$11,A4) -> 3 | E4: =SUMIF('Sub-principles'!$B$2:$B$11,A4,'Sub-principles'!$E$2:$E$11) -> 32 | F4: =_xlfn.TEXTJOIN(", ",TRUE(),IF(COUNTIFS(tl_principle,$A4,tl_sdg,1)>0,"1",""),IF(COUNTIFS(tl_principle,$A4,tl_sdg,2)>0,"2",""),IF(COUNTIFS(tl_principle,$A4,tl_sdg,3)>0,"3",""),IF(COUNTIFS(tl_principle,$A4,tl_sdg,4)>0,"4",""),IF(COUNTIFS(tl_principle,$A4,tl_sdg,5)>0,"5",""),IF(COUNTIFS(tl_principle,$A4,tl_sdg,6)>0,"6",""),IF(COUNTIFS(tl_principle,$A4,tl_sdg,7)>0,"7",""),IF(COUNTIFS(tl_principle,$A4,tl_sdg,8)>0,"8",""),IF(COUNTIFS(tl_principle,$A4,tl_sdg,9)>0,"9",""),IF(COUNTIFS(tl_principle,$A4,tl_sdg,10)>0,"10",""),IF(COUNTIFS(tl_principle,$A4,tl_sdg,11)>0,"11",""),IF(COUNTIFS(tl_principle,$A4,tl_sdg,12)>0,"12",""),IF(COUNTIFS(tl_principle,$A4,tl_sdg,13)>0,"13",""),IF(COUNTIFS(tl_principle,$A4,tl_sdg,14)>0,"14",""),IF(COUNTIFS(tl_principle,$A4,tl_sdg,15)>0,"15",""),IF(COUNTIFS(tl_principle,$A4,tl_sdg,16)>0,"16",""),IF(COUNTIFS(tl_principle,$A4,tl_sdg,17)>0,"17","")) -> 1, 4, 8, 9, 10, 11, 12, 16, 17 | G4: =_xlfn.TEXTJOIN(", ",TRUE(),IF(COUNTIFS(tl_principle,$A4,tl_sdg,1,tl_align,"Primary")>0,"1",""),IF(COUNTIFS(tl_principle,$A4,tl_sdg,2,tl_align,"Primary")>0,"2",""),IF(COUNTIFS(tl_principle,$A4,tl_sdg,3,tl_align,"Primary")>0,"3",""),IF(COUNTIFS(tl_principle,$A4,tl_sdg,4,tl_align,"Primary")>0,"4",""),IF(COUNTIFS(tl_principle,$A4,tl_sdg,5,tl_align,"Primary")>0,"5",""),IF(COUNTIFS(tl_principle,$A4,tl_sdg,6,tl_align,"Primary")>0,"6",""),IF(COUNTIFS(tl_principle,$A4,tl_sdg,7,tl_align,"Primary")>0,"7",""),IF(COUNTIFS(tl_principle,$A4,tl_sdg,8,tl_align,"Primary")>0,"8",""),IF(COUNTIFS(tl_principle,$A4,tl_sdg,9,tl_align,"Primary")>0,"9",""),IF(COUNTIFS(tl_principle,$A4,tl_sdg,10,tl_align,"Primary")>0,"10",""),IF(COUNTIFS(tl_principle,$A4,tl_sdg,11,tl_align,"Primary")>0,"11",""),IF(COUNTIFS(tl_principle,$A4,tl_sdg,12,tl_align,"Primary")>0,"12",""),IF(COUNTIFS(tl_principle,$A4,tl_sdg,13,tl_align,"Primary")>0,"13",""),IF(COUNTIFS(tl_principle,$A4,tl_sdg,14,tl_align,"Primary")>0,"14",""),IF(COUNTIFS(tl_principle,$A4,tl_sdg,15,tl_align,"Primary")>0,"15",""),IF(COUNTIFS(tl_principle,$A4,tl_sdg,16,tl_align,"Primary")>0,"16",""),IF(COUNTIFS(tl_principle,$A4,tl_sdg,17,tl_align,"Primary")>0,"17","")) -> 10, 11, 17 | H4: =COUNTIF(tl_principle,A4) -> 20 | I4: =SUMIF('Sub-principles'!$B$2:$B$11,A4,'Sub-principles'!$M$2:$M$11) -> 29
A5: PP4 | B5: Transversal planning and governance | C5: Governance | D5: =COUNTIF('Sub-principles'!$B$2:$B$11,A5) -> 2 | E5: =SUMIF('Sub-principles'!$B$2:$B$11,A5,'Sub-principles'!$E$2:$E$11) -> 28 | F5: =_xlfn.TEXTJOIN(", ",TRUE(),IF(COUNTIFS(tl_principle,$A5,tl_sdg,1)>0,"1",""),IF(COUNTIFS(tl_principle,$A5,tl_sdg,2)>0,"2",""),IF(COUNTIFS(tl_principle,$A5,tl_sdg,3)>0,"3",""),IF(COUNTIFS(tl_principle,$A5,tl_sdg,4)>0,"4",""),IF(COUNTIFS(tl_principle,$A5,tl_sdg,5)>0,"5",""),IF(COUNTIFS(tl_principle,$A5,tl_sdg,6)>0,"6",""),IF(COUNTIFS(tl_principle,$A5,tl_sdg,7)>0,"7",""),IF(COUNTIFS(tl_principle,$A5,tl_sdg,8)>0,"8",""),IF(COUNTIFS(tl_principle,$A5,tl_sdg,9)>0,"9",""),IF(COUNTIFS(tl_principle,$A5,tl_sdg,10)>0,"10",""),IF(COUNTIFS(tl_principle,$A5,tl_sdg,11)>0,"11",""),IF(COUNTIFS(tl_principle,$A5,tl_sdg,12)>0,"12",""),IF(COUNTIFS(tl_principle,$A5,tl_sdg,13)>0,"13",""),IF(COUNTIFS(tl_principle,$A5,tl_sdg,14)>0,"14",""),IF(COUNTIFS(tl_principle,$A5,tl_sdg,15)>0,"15",""),IF(COUNTIFS(tl_principle,$A5,tl_sdg,16)>0,"16",""),IF(COUNTIFS(tl_principle,$A5,tl_sdg,17)>0,"17","")) -> 8, 10, 11, 16, 17 | G5: =_xlfn.TEXTJOIN(", ",TRUE(),IF(COUNTIFS(tl_principle,$A5,tl_sdg,1,tl_align,"Primary")>0,"1",""),IF(COUNTIFS(tl_principle,$A5,tl_sdg,2,tl_align,"Primary")>0,"2",""),IF(COUNTIFS(tl_principle,$A5,tl_sdg,3,tl_align,"Primary")>0,"3",""),IF(COUNTIFS(tl_principle,$A5,tl_sdg,4,tl_align,"Primary")>0,"4",""),IF(COUNTIFS(tl_principle,$A5,tl_sdg,5,tl_align,"Primary")>0,"5",""),IF(COUNTIFS(tl_principle,$A5,tl_sdg,6,tl_align,"Primary")>0,"6",""),IF(COUNTIFS(tl_principle,$A5,tl_sdg,7,tl_align,"Primary")>0,"7",""),IF(COUNTIFS(tl_principle,$A5,tl_sdg,8,tl_align,"Primary")>0,"8",""),IF(COUNTIFS(tl_principle,$A5,tl_sdg,9,tl_align,"Primary")>0,"9",""),IF(COUNTIFS(tl_principle,$A5,tl_sdg,10,tl_align,"Primary")>0,"10",""),IF(COUNTIFS(tl_principle,$A5,tl_sdg,11,tl_align,"Primary")>0,"11",""),IF(COUNTIFS(tl_principle,$A5,tl_sdg,12,tl_align,"Primary")>0,"12",""),IF(COUNTIFS(tl_principle,$A5,tl_sdg,13,tl_align,"Primary")>0,"13",""),IF(COUNTIFS(tl_principle,$A5,tl_sdg,14,tl_align,"Primary")>0,"14",""),IF(COUNTIFS(tl_principle,$A5,tl_sdg,15,tl_align,"Primary")>0,"15",""),IF(COUNTIFS(tl_principle,$A5,tl_sdg,16,tl_align,"Primary")>0,"16",""),IF(COUNTIFS(tl_principle,$A5,tl_sdg,17,tl_align,"Primary")>0,"17","")) -> 16 | H5: =COUNTIF(tl_principle,A5) -> 11 | I5: =SUMIF('Sub-principles'!$B$2:$B$11,A5,'Sub-principles'!$M$2:$M$11) -> 16
B6: Total | D6: =SUM(D2:D5) -> 10 | E6: =SUM(E2:E5) -> 100 | H6: =SUM(H2:H5) -> 66 | I6: =SUM(I2:I5) -> 103

Sheet Sub-principles
A1: Sub-principle | B1: Principle | C1: Name | D1: Short name | E1: Weight | F1: Key policy criterion | G1: Assessment question | H1: Primary SDGs | I1: Secondary SDGs | J1: Primary targets | K1: Secondary targets | L1: Target links | M1: Indicator links | N1: Alignment rationale | O1: Prescripts
A2: PP1.1 | B2: PP1 | C2: Infrastructure Design and Material Innovation | D2: Design & material innovation | E2: 8 | F2: Integrate prescribed planning frameworks to promote innovation in infrastructure design, and infrastructure material use aligned to national and local development goals. | G2: Does the project offer clear evidence of compliance to design innovations pertaining to key planning prescripts and construction material use across the 3 spheres of government? | H2: =_xlfn.TEXTJOIN(", ",TRUE(),IF(COUNTIFS(tl_sub,$A2,tl_sdg,1,tl_align,"Primary")>0,"1",""),IF(COUNTIFS(tl_sub,$A2,tl_sdg,2,tl_align,"Primary")>0,"2",""),IF(COUNTIFS(tl_sub,$A2,tl_sdg,3,tl_align,"Primary")>0,"3",""),IF(COUNTIFS(tl_sub,$A2,tl_sdg,4,tl_align,"Primary")>0,"4",""),IF(COUNTIFS(tl_sub,$A2,tl_sdg,5,tl_align,"Primary")>0,"5",""),IF(COUNTIFS(tl_sub,$A2,tl_sdg,6,tl_align,"Primary")>0,"6",""),IF(COUNTIFS(tl_sub,$A2,tl_sdg,7,tl_align,"Primary")>0,"7",""),IF(COUNTIFS(tl_sub,$A2,tl_sdg,8,tl_align,"Primary")>0,"8",""),IF(COUNTIFS(tl_sub,$A2,tl_sdg,9,tl_align,"Primary")>0,"9",""),IF(COUNTIFS(tl_sub,$A2,tl_sdg,10,tl_align,"Primary")>0,"10",""),IF(COUNTIFS(tl_sub,$A2,tl_sdg,11,tl_align,"Primary")>0,"11",""),IF(COUNTIFS(tl_sub,$A2,tl_sdg,12,tl_align,"Primary")>0,"12",""),IF(COUNTIFS(tl_sub,$A2,tl_sdg,13,tl_align,"Primary")>0,"13",""),IF(COUNTIFS(tl_sub,$A2,tl_sdg,14,tl_align,"Primary")>0,"14",""),IF(COUNTIFS(tl_sub,$A2,tl_sdg,15,tl_align,"Primary")>0,"15",""),IF(COUNTIFS(tl_sub,$A2,tl_sdg,16,tl_align,"Primary")>0,"16",""),IF(COUNTIFS(tl_sub,$A2,tl_sdg,17,tl_align,"Primary")>0,"17","")) -> 9 | I2: =_xlfn.TEXTJOIN(", ",TRUE(),IF(COUNTIFS(tl_sub,$A2,tl_sdg,1,tl_align,"Secondary")>0,"1",""),IF(COUNTIFS(tl_sub,$A2,tl_sdg,2,tl_align,"Secondary")>0,"2",""),IF(COUNTIFS(tl_sub,$A2,tl_sdg,3,tl_align,"Secondary")>0,"3",""),IF(COUNTIFS(tl_sub,$A2,tl_sdg,4,tl_align,"Secondary")>0,"4",""),IF(COUNTIFS(tl_sub,$A2,tl_sdg,5,tl_align,"Secondary")>0,"5",""),IF(COUNTIFS(tl_sub,$A2,tl_sdg,6,tl_align,"Secondary")>0,"6",""),IF(COUNTIFS(tl_sub,$A2,tl_sdg,7,tl_align,"Secondary")>0,"7",""),IF(COUNTIFS(tl_sub,$A2,tl_sdg,8,tl_align,"Secondary")>0,"8",""),IF(COUNTIFS(tl_sub,$A2,tl_sdg,9,tl_align,"Secondary")>0,"9",""),IF(COUNTIFS(tl_sub,$A2,tl_sdg,10,tl_align,"Secondary")>0,"10",""),IF(COUNTIFS(tl_sub,$A2,tl_sdg,11,tl_align,"Secondary")>0,"11",""),IF(COUNTIFS(tl_sub,$A2,tl_sdg,12,tl_align,"Secondary")>0,"12",""),IF(COUNTIFS(tl_sub,$A2,tl_sdg,13,tl_align,"Secondary")>0,"13",""),IF(COUNTIFS(tl_sub,$A2,tl_sdg,14,tl_align,"Secondary")>0,"14",""),IF(COUNTIFS(tl_sub,$A2,tl_sdg,15,tl_align,"Secondary")>0,"15",""),IF(COUNTIFS(tl_sub,$A2,tl_sdg,16,tl_align,"Secondary")>0,"16",""),IF(COUNTIFS(tl_sub,$A2,tl_sdg,17,tl_align,"Secondary")>0,"17","")) -> 8, 11, 12 | J2: 9.1, 9.4, 9.5 | K2: 8.2, 11.3, 12.2 | L2: =COUNTIF(tl_sub,A2) -> 6 | M2: =COUNTIF(il_sub,A2) -> 10 | N2: Innovative, sustainable infrastructure design and material use improve resource efficiency while aligning projects with national and local development plans. | O2: NT/PFMA; MTEF; NDP; NIP 2050; NSDF; NLTF; WCSDF 2035; MSDF; PLTF; PSP 2025-2030; G4J; WCIF; WCEIIF; CC response strategy; Green BCSA; SABS; BSA; NDC; CCA 2024; JTF; WCCCRS; MTSF; CIDB; CIF; CEF; C-AMP (GIAMA); U-AMP (GIAMA).
A3: PP1.2 | B3: PP1 | C3: ICT Innovation | D3: ICT innovation | E3: 8 | F3: Promote innovation in ICT to enhance ease of doing business and government processes, driving economic and governance efficiencies. | G3: Does the project offer clear evidence of compliance to ICT innovations and/or efficiencies like ease-of-doing-business and/or ease-of-doing-government? | H3: =_xlfn.TEXTJOIN(", ",TRUE(),IF(COUNTIFS(tl_sub,$A3,tl_sdg,1,tl_align,"Primary")>0,"1",""),IF(COUNTIFS(tl_sub,$A3,tl_sdg,2,tl_align,"Primary")>0,"2",""),IF(COUNTIFS(tl_sub,$A3,tl_sdg,3,tl_align,"Primary")>0,"3",""),IF(COUNTIFS(tl_sub,$A3,tl_sdg,4,tl_align,"Primary")>0,"4",""),IF(COUNTIFS(tl_sub,$A3,tl_sdg,5,tl_align,"Primary")>0,"5",""),IF(COUNTIFS(tl_sub,$A3,tl_sdg,6,tl_align,"Primary")>0,"6",""),IF(COUNTIFS(tl_sub,$A3,tl_sdg,7,tl_align,"Primary")>0,"7",""),IF(COUNTIFS(tl_sub,$A3,tl_sdg,8,tl_align,"Primary")>0,"8",""),IF(COUNTIFS(tl_sub,$A3,tl_sdg,9,tl_align,"Primary")>0,"9",""),IF(COUNTIFS(tl_sub,$A3,tl_sdg,10,tl_align,"Primary")>0,"10",""),IF(COUNTIFS(tl_sub,$A3,tl_sdg,11,tl_align,"Primary")>0,"11",""),IF(COUNTIFS(tl_sub,$A3,tl_sdg,12,tl_align,"Primary")>0,"12",""),IF(COUNTIFS(tl_sub,$A3,tl_sdg,13,tl_align,"Primary")>0,"13",""),IF(COUNTIFS(tl_sub,$A3,tl_sdg,14,tl_align,"Primary")>0,"14",""),IF(COUNTIFS(tl_sub,$A3,tl_sdg,15,tl_align,"Primary")>0,"15",""),IF(COUNTIFS(tl_sub,$A3,tl_sdg,16,tl_align,"Primary")>0,"16",""),IF(COUNTIFS(tl_sub,$A3,tl_sdg,17,tl_align,"Primary")>0,"17","")) -> 9 | I3: =_xlfn.TEXTJOIN(", ",TRUE(),IF(COUNTIFS(tl_sub,$A3,tl_sdg,1,tl_align,"Secondary")>0,"1",""),IF(COUNTIFS(tl_sub,$A3,tl_sdg,2,tl_align,"Secondary")>0,"2",""),IF(COUNTIFS(tl_sub,$A3,tl_sdg,3,tl_align,"Secondary")>0,"3",""),IF(COUNTIFS(tl_sub,$A3,tl_sdg,4,tl_align,"Secondary")>0,"4",""),IF(COUNTIFS(tl_sub,$A3,tl_sdg,5,tl_align,"Secondary")>0,"5",""),IF(COUNTIFS(tl_sub,$A3,tl_sdg,6,tl_align,"Secondary")>0,"6",""),IF(COUNTIFS(tl_sub,$A3,tl_sdg,7,tl_align,"Secondary")>0,"7",""),IF(COUNTIFS(tl_sub,$A3,tl_sdg,8,tl_align,"Secondary")>0,"8",""),IF(COUNTIFS(tl_sub,$A3,tl_sdg,9,tl_align,"Secondary")>0,"9",""),IF(COUNTIFS(tl_sub,$A3,tl_sdg,10,tl_align,"Secondary")>0,"10",""),IF(COUNTIFS(tl_sub,$A3,tl_sdg,11,tl_align,"Secondary")>0,"11",""),IF(COUNTIFS(tl_sub,$A3,tl_sdg,12,tl_align,"Secondary")>0,"12",""),IF(COUNTIFS(tl_sub,$A3,tl_sdg,13,tl_align,"Secondary")>0,"13",""),IF(COUNTIFS(tl_sub,$A3,tl_sdg,14,tl_align,"Secondary")>0,"14",""),IF(COUNTIFS(tl_sub,$A3,tl_sdg,15,tl_align,"Secondary")>0,"15",""),IF(COUNTIFS(tl_sub,$A3,tl_sdg,16,tl_align,"Secondary")>0,"16",""),IF(COUNTIFS(tl_sub,$A3,tl_sdg,17,tl_align,"Secondary")>0,"17","")) -> 8, 16, 17 | J3: 9.5, 9.c | K3: 8.2, 16.6, 16.10, 17.8 | L3: =COUNTIF(tl_sub,A3) -> 6 | M3: =COUNTIF(il_sub,A3) -> 9 | N3: Digital infrastructure and ICT innovation improve business processes, public-service delivery, information access and institutional efficiency. | O3: NDP; SITA; G4J; WCIF; PSP 2025-2030; PLTF; MTSF.
A4: PP2.1 | B4: PP2 | C4: Resilient Infrastructure Design and Risk Mitigation | D4: Resilient design & risk | E4: 8 | F4: Align infrastructure design with resilience principles to address climate change, sustainability, and regenerative practices. It must also address water, energy, and disaster management through proactive risk mitigation strategies and policies. | G4: Does the project offer clear evidence of innovations that foster resilience and regenerative aspects of the infrastructure value chain; and are there risk mitigation strategies in place? | H4: =_xlfn.TEXTJOIN(", ",TRUE(),IF(COUNTIFS(tl_sub,$A4,tl_sdg,1,tl_align,"Primary")>0,"1",""),IF(COUNTIFS(tl_sub,$A4,tl_sdg,2,tl_align,"Primary")>0,"2",""),IF(COUNTIFS(tl_sub,$A4,tl_sdg,3,tl_align,"Primary")>0,"3",""),IF(COUNTIFS(tl_sub,$A4,tl_sdg,4,tl_align,"Primary")>0,"4",""),IF(COUNTIFS(tl_sub,$A4,tl_sdg,5,tl_align,"Primary")>0,"5",""),IF(COUNTIFS(tl_sub,$A4,tl_sdg,6,tl_align,"Primary")>0,"6",""),IF(COUNTIFS(tl_sub,$A4,tl_sdg,7,tl_align,"Primary")>0,"7",""),IF(COUNTIFS(tl_sub,$A4,tl_sdg,8,tl_align,"Primary")>0,"8",""),IF(COUNTIFS(tl_sub,$A4,tl_sdg,9,tl_align,"Primary")>0,"9",""),IF(COUNTIFS(tl_sub,$A4,tl_sdg,10,tl_align,"Primary")>0,"10",""),IF(COUNTIFS(tl_sub,$A4,tl_sdg,11,tl_align,"Primary")>0,"11",""),IF(COUNTIFS(tl_sub,$A4,tl_sdg,12,tl_align,"Primary")>0,"12",""),IF(COUNTIFS(tl_sub,$A4,tl_sdg,13,tl_align,"Primary")>0,"13",""),IF(COUNTIFS(tl_sub,$A4,tl_sdg,14,tl_align,"Primary")>0,"14",""),IF(COUNTIFS(tl_sub,$A4,tl_sdg,15,tl_align,"Primary")>0,"15",""),IF(COUNTIFS(tl_sub,$A4,tl_sdg,16,tl_align,"Primary")>0,"16",""),IF(COUNTIFS(tl_sub,$A4,tl_sdg,17,tl_align,"Primary")>0,"17","")) -> 9, 13 | I4: =_xlfn.TEXTJOIN(", ",TRUE(),IF(COUNTIFS(tl_sub,$A4,tl_sdg,1,tl_align,"Secondary")>0,"1",""),IF(COUNTIFS(tl_sub,$A4,tl_sdg,2,tl_align,"Secondary")>0,"2",""),IF(COUNTIFS(tl_sub,$A4,tl_sdg,3,tl_align,"Secondary")>0,"3",""),IF(COUNTIFS(tl_sub,$A4,tl_sdg,4,tl_align,"Secondary")>0,"4",""),IF(COUNTIFS(tl_sub,$A4,tl_sdg,5,tl_align,"Secondary")>0,"5",""),IF(COUNTIFS(tl_sub,$A4,tl_sdg,6,tl_align,"Secondary")>0,"6",""),IF(COUNTIFS(tl_sub,$A4,tl_sdg,7,tl_align,"Secondary")>0,"7",""),IF(COUNTIFS(tl_sub,$A4,tl_sdg,8,tl_align,"Secondary")>0,"8",""),IF(COUNTIFS(tl_sub,$A4,tl_sdg,9,tl_align,"Secondary")>0,"9",""),IF(COUNTIFS(tl_sub,$A4,tl_sdg,10,tl_align,"Secondary")>0,"10",""),IF(COUNTIFS(tl_sub,$A4,tl_sdg,11,tl_align,"Secondary")>0,"11",""),IF(COUNTIFS(tl_sub,$A4,tl_sdg,12,tl_align,"Secondary")>0,"12",""),IF(COUNTIFS(tl_sub,$A4,tl_sdg,13,tl_align,"Secondary")>0,"13",""),IF(COUNTIFS(tl_sub,$A4,tl_sdg,14,tl_align,"Secondary")>0,"14",""),IF(COUNTIFS(tl_sub,$A4,tl_sdg,15,tl_align,"Secondary")>0,"15",""),IF(COUNTIFS(tl_sub,$A4,tl_sdg,16,tl_align,"Secondary")>0,"16",""),IF(COUNTIFS(tl_sub,$A4,tl_sdg,17,tl_align,"Secondary")>0,"17","")) -> 6, 7, 11, 12 | J4: 9.1, 13.1, 13.2 | K4: 6.4, 6.5, 7.2, 7.3, 11.5, 11.b, 12.2 | L4: =COUNTIF(tl_sub,A4) -> 10 | M4: =COUNTIF(il_sub,A4) -> 20 | N4: Directly addresses climate resilience, disaster-risk reduction, water and energy management, sustainability and regenerative design. | O4: WCIF; PLTF; NDC; CCA 2024; JTF; WCCCRS; WCEIIF; Green BCSA; UIDG; CIDB; CIF; CEF; IGM; C-AMP (GIAMA); U-AMP (GIAMA).
A5: PP2.2 | B5: PP2 | C5: Infrastructure Planning for Systemic Alignment | D5: Systemic planning alignment | E5: 8 | F5: Integrated and collaborative planning ensures alignment across spatial, economic, and environmental systems, serving as the foundation for sustainable infrastructure value chains and ecosystems. | G5: Does the project offer clear evidence of alignment, integration and collaboration across the WC infrastructure ecosystem? | H5: =_xlfn.TEXTJOIN(", ",TRUE(),IF(COUNTIFS(tl_sub,$A5,tl_sdg,1,tl_align,"Primary")>0,"1",""),IF(COUNTIFS(tl_sub,$A5,tl_sdg,2,tl_align,"Primary")>0,"2",""),IF(COUNTIFS(tl_sub,$A5,tl_sdg,3,tl_align,"Primary")>0,"3",""),IF(COUNTIFS(tl_sub,$A5,tl_sdg,4,tl_align,"Primary")>0,"4",""),IF(COUNTIFS(tl_sub,$A5,tl_sdg,5,tl_align,"Primary")>0,"5",""),IF(COUNTIFS(tl_sub,$A5,tl_sdg,6,tl_align,"Primary")>0,"6",""),IF(COUNTIFS(tl_sub,$A5,tl_sdg,7,tl_align,"Primary")>0,"7",""),IF(COUNTIFS(tl_sub,$A5,tl_sdg,8,tl_align,"Primary")>0,"8",""),IF(COUNTIFS(tl_sub,$A5,tl_sdg,9,tl_align,"Primary")>0,"9",""),IF(COUNTIFS(tl_sub,$A5,tl_sdg,10,tl_align,"Primary")>0,"10",""),IF(COUNTIFS(tl_sub,$A5,tl_sdg,11,tl_align,"Primary")>0,"11",""),IF(COUNTIFS(tl_sub,$A5,tl_sdg,12,tl_align,"Primary")>0,"12",""),IF(COUNTIFS(tl_sub,$A5,tl_sdg,13,tl_align,"Primary")>0,"13",""),IF(COUNTIFS(tl_sub,$A5,tl_sdg,14,tl_align,"Primary")>0,"14",""),IF(COUNTIFS(tl_sub,$A5,tl_sdg,15,tl_align,"Primary")>0,"15",""),IF(COUNTIFS(tl_sub,$A5,tl_sdg,16,tl_align,"Primary")>0,"16",""),IF(COUNTIFS(tl_sub,$A5,tl_sdg,17,tl_align,"Primary")>0,"17","")) -> 11 | I5: =_xlfn.TEXTJOIN(", ",TRUE(),IF(COUNTIFS(tl_sub,$A5,tl_sdg,1,tl_align,"Secondary")>0,"1",""),IF(COUNTIFS(tl_sub,$A5,tl_sdg,2,tl_align,"Secondary")>0,"2",""),IF(COUNTIFS(tl_sub,$A5,tl_sdg,3,tl_align,"Secondary")>0,"3",""),IF(COUNTIFS(tl_sub,$A5,tl_sdg,4,tl_align,"Secondary")>0,"4",""),IF(COUNTIFS(tl_sub,$A5,tl_sdg,5,tl_align,"Secondary")>0,"5",""),IF(COUNTIFS(tl_sub,$A5,tl_sdg,6,tl_align,"Secondary")>0,"6",""),IF(COUNTIFS(tl_sub,$A5,tl_sdg,7,tl_align,"Secondary")>0,"7",""),IF(COUNTIFS(tl_sub,$A5,tl_sdg,8,tl_align,"Secondary")>0,"8",""),IF(COUNTIFS(tl_sub,$A5,tl_sdg,9,tl_align,"Secondary")>0,"9",""),IF(COUNTIFS(tl_sub,$A5,tl_sdg,10,tl_align,"Secondary")>0,"10",""),IF(COUNTIFS(tl_sub,$A5,tl_sdg,11,tl_align,"Secondary")>0,"11",""),IF(COUNTIFS(tl_sub,$A5,tl_sdg,12,tl_align,"Secondary")>0,"12",""),IF(COUNTIFS(tl_sub,$A5,tl_sdg,13,tl_align,"Secondary")>0,"13",""),IF(COUNTIFS(tl_sub,$A5,tl_sdg,14,tl_align,"Secondary")>0,"14",""),IF(COUNTIFS(tl_sub,$A5,tl_sdg,15,tl_align,"Secondary")>0,"15",""),IF(COUNTIFS(tl_sub,$A5,tl_sdg,16,tl_align,"Secondary")>0,"16",""),IF(COUNTIFS(tl_sub,$A5,tl_sdg,17,tl_align,"Secondary")>0,"17","")) -> 9, 13, 17 | J5: 11.3, 11.a | K5: 9.1, 13.2, 17.14, 17.16, 17.17 | L5: =COUNTIF(tl_sub,A5) -> 7 | M5: =COUNTIF(il_sub,A5) -> 10 | N5: Integrated spatial, economic and environmental planning creates coherent infrastructure systems and sustainable value chains. | O5: NT/PFMA; MTEF; NDP; NIP 2050; NSDF; NLTF; WCSDF 2035; MSDF; PLTF; PSP 2025-2030; G4J; WCIF; IUDF; IDWRP; EPWP; GPS (DEA&DP 2024); MFMA; CEF; UIDG; COGTA; CIDB; LTFP; IGM; SDBIP; C-AMP (GIAMA); U-AMP (GIAMA).
A6: PP2.3 | B6: PP2 | C6: Localised Resource Utilisation | D6: Localised resources | E6: 8 | F6: Reduce socio-ecological costs by sourcing inputs locally and minimising resource transportation needs (this includes consideration of Biodiversity Offsets). | G6: Does the project offer clear evidence of innovations that foster resilience, sustainable and regenerative aspects in the infrastructure and project value chains at a local level? | H6: =_xlfn.TEXTJOIN(", ",TRUE(),IF(COUNTIFS(tl_sub,$A6,tl_sdg,1,tl_align,"Primary")>0,"1",""),IF(COUNTIFS(tl_sub,$A6,tl_sdg,2,tl_align,"Primary")>0,"2",""),IF(COUNTIFS(tl_sub,$A6,tl_sdg,3,tl_align,"Primary")>0,"3",""),IF(COUNTIFS(tl_sub,$A6,tl_sdg,4,tl_align,"Primary")>0,"4",""),IF(COUNTIFS(tl_sub,$A6,tl_sdg,5,tl_align,"Primary")>0,"5",""),IF(COUNTIFS(tl_sub,$A6,tl_sdg,6,tl_align,"Primary")>0,"6",""),IF(COUNTIFS(tl_sub,$A6,tl_sdg,7,tl_align,"Primary")>0,"7",""),IF(COUNTIFS(tl_sub,$A6,tl_sdg,8,tl_align,"Primary")>0,"8",""),IF(COUNTIFS(tl_sub,$A6,tl_sdg,9,tl_align,"Primary")>0,"9",""),IF(COUNTIFS(tl_sub,$A6,tl_sdg,10,tl_align,"Primary")>0,"10",""),IF(COUNTIFS(tl_sub,$A6,tl_sdg,11,tl_align,"Primary")>0,"11",""),IF(COUNTIFS(tl_sub,$A6,tl_sdg,12,tl_align,"Primary")>0,"12",""),IF(COUNTIFS(tl_sub,$A6,tl_sdg,13,tl_align,"Primary")>0,"13",""),IF(COUNTIFS(tl_sub,$A6,tl_sdg,14,tl_align,"Primary")>0,"14",""),IF(COUNTIFS(tl_sub,$A6,tl_sdg,15,tl_align,"Primary")>0,"15",""),IF(COUNTIFS(tl_sub,$A6,tl_sdg,16,tl_align,"Primary")>0,"16",""),IF(COUNTIFS(tl_sub,$A6,tl_sdg,17,tl_align,"Primary")>0,"17","")) -> 12 | I6: =_xlfn.TEXTJOIN(", ",TRUE(),IF(COUNTIFS(tl_sub,$A6,tl_sdg,1,tl_align,"Secondary")>0,"1",""),IF(COUNTIFS(tl_sub,$A6,tl_sdg,2,tl_align,"Secondary")>0,"2",""),IF(COUNTIFS(tl_sub,$A6,tl_sdg,3,tl_align,"Secondary")>0,"3",""),IF(COUNTIFS(tl_sub,$A6,tl_sdg,4,tl_align,"Secondary")>0,"4",""),IF(COUNTIFS(tl_sub,$A6,tl_sdg,5,tl_align,"Secondary")>0,"5",""),IF(COUNTIFS(tl_sub,$A6,tl_sdg,6,tl_align,"Secondary")>0,"6",""),IF(COUNTIFS(tl_sub,$A6,tl_sdg,7,tl_align,"Secondary")>0,"7",""),IF(COUNTIFS(tl_sub,$A6,tl_sdg,8,tl_align,"Secondary")>0,"8",""),IF(COUNTIFS(tl_sub,$A6,tl_sdg,9,tl_align,"Secondary")>0,"9",""),IF(COUNTIFS(tl_sub,$A6,tl_sdg,10,tl_align,"Secondary")>0,"10",""),IF(COUNTIFS(tl_sub,$A6,tl_sdg,11,tl_align,"Secondary")>0,"11",""),IF(COUNTIFS(tl_sub,$A6,tl_sdg,12,tl_align,"Secondary")>0,"12",""),IF(COUNTIFS(tl_sub,$A6,tl_sdg,13,tl_align,"Secondary")>0,"13",""),IF(COUNTIFS(tl_sub,$A6,tl_sdg,14,tl_align,"Secondary")>0,"14",""),IF(COUNTIFS(tl_sub,$A6,tl_sdg,15,tl_align,"Secondary")>0,"15",""),IF(COUNTIFS(tl_sub,$A6,tl_sdg,16,tl_align,"Secondary")>0,"16",""),IF(COUNTIFS(tl_sub,$A6,tl_sdg,17,tl_align,"Secondary")>0,"17","")) -> 8, 9, 11, 13 | J6: 12.2, 12.7 | K6: 8.3, 9.4, 11.6, 13.2 | L6: =COUNTIF(tl_sub,A6) -> 6 | M6: =COUNTIF(il_sub,A6) -> 9 | N6: Local sourcing and sustainable procurement reduce transport impacts, embodied emissions and resource costs while stimulating local economies. | O6: NDC; CCA 2024; JTF; Green BCSA; King IV; WCIF; WCCCRS; WCEIIF; CIDB; C-AMP (GIAMA); U-AMP (GIAMA).
A7: PP3.1 | B7: PP3 | C7: Geolocation relative to Spatial Zones | D7: Spatial-zone geolocation | E7: 8 | F7: Align infrastructure development to counter spatial inaccessibility via equitable access, capacity building and knowledge management of spatial justice. | G7: Does the project offer clear evidence of sustainable stakeholder value fostering trust in context of spatial justice and improved access to infrastructure? | H7: =_xlfn.TEXTJOIN(", ",TRUE(),IF(COUNTIFS(tl_sub,$A7,tl_sdg,1,tl_align,"Primary")>0,"1",""),IF(COUNTIFS(tl_sub,$A7,tl_sdg,2,tl_align,"Primary")>0,"2",""),IF(COUNTIFS(tl_sub,$A7,tl_sdg,3,tl_align,"Primary")>0,"3",""),IF(COUNTIFS(tl_sub,$A7,tl_sdg,4,tl_align,"Primary")>0,"4",""),IF(COUNTIFS(tl_sub,$A7,tl_sdg,5,tl_align,"Primary")>0,"5",""),IF(COUNTIFS(tl_sub,$A7,tl_sdg,6,tl_align,"Primary")>0,"6",""),IF(COUNTIFS(tl_sub,$A7,tl_sdg,7,tl_align,"Primary")>0,"7",""),IF(COUNTIFS(tl_sub,$A7,tl_sdg,8,tl_align,"Primary")>0,"8",""),IF(COUNTIFS(tl_sub,$A7,tl_sdg,9,tl_align,"Primary")>0,"9",""),IF(COUNTIFS(tl_sub,$A7,tl_sdg,10,tl_align,"Primary")>0,"10",""),IF(COUNTIFS(tl_sub,$A7,tl_sdg,11,tl_align,"Primary")>0,"11",""),IF(COUNTIFS(tl_sub,$A7,tl_sdg,12,tl_align,"Primary")>0,"12",""),IF(COUNTIFS(tl_sub,$A7,tl_sdg,13,tl_align,"Primary")>0,"13",""),IF(COUNTIFS(tl_sub,$A7,tl_sdg,14,tl_align,"Primary")>0,"14",""),IF(COUNTIFS(tl_sub,$A7,tl_sdg,15,tl_align,"Primary")>0,"15",""),IF(COUNTIFS(tl_sub,$A7,tl_sdg,16,tl_align,"Primary")>0,"16",""),IF(COUNTIFS(tl_sub,$A7,tl_sdg,17,tl_align,"Primary")>0,"17","")) -> 11 | I7: =_xlfn.TEXTJOIN(", ",TRUE(),IF(COUNTIFS(tl_sub,$A7,tl_sdg,1,tl_align,"Secondary")>0,"1",""),IF(COUNTIFS(tl_sub,$A7,tl_sdg,2,tl_align,"Secondary")>0,"2",""),IF(COUNTIFS(tl_sub,$A7,tl_sdg,3,tl_align,"Secondary")>0,"3",""),IF(COUNTIFS(tl_sub,$A7,tl_sdg,4,tl_align,"Secondary")>0,"4",""),IF(COUNTIFS(tl_sub,$A7,tl_sdg,5,tl_align,"Secondary")>0,"5",""),IF(COUNTIFS(tl_sub,$A7,tl_sdg,6,tl_align,"Secondary")>0,"6",""),IF(COUNTIFS(tl_sub,$A7,tl_sdg,7,tl_align,"Secondary")>0,"7",""),IF(COUNTIFS(tl_sub,$A7,tl_sdg,8,tl_align,"Secondary")>0,"8",""),IF(COUNTIFS(tl_sub,$A7,tl_sdg,9,tl_align,"Secondary")>0,"9",""),IF(COUNTIFS(tl_sub,$A7,tl_sdg,10,tl_align,"Secondary")>0,"10",""),IF(COUNTIFS(tl_sub,$A7,tl_sdg,11,tl_align,"Secondary")>0,"11",""),IF(COUNTIFS(tl_sub,$A7,tl_sdg,12,tl_align,"Secondary")>0,"12",""),IF(COUNTIFS(tl_sub,$A7,tl_sdg,13,tl_align,"Secondary")>0,"13",""),IF(COUNTIFS(tl_sub,$A7,tl_sdg,14,tl_align,"Secondary")>0,"14",""),IF(COUNTIFS(tl_sub,$A7,tl_sdg,15,tl_align,"Secondary")>0,"15",""),IF(COUNTIFS(tl_sub,$A7,tl_sdg,16,tl_align,"Secondary")>0,"16",""),IF(COUNTIFS(tl_sub,$A7,tl_sdg,17,tl_align,"Secondary")>0,"17","")) -> 4, 9, 10 | J7: 11.1, 11.2, 11.3, 11.a | K7: 4.4, 9.1, 10.2 | L7: =COUNTIF(tl_sub,A7) -> 7 | M7: =COUNTIF(il_sub,A7) -> 9 | N7: Locating infrastructure strategically can reduce spatial exclusion and improve equitable access to services, opportunities, knowledge and capacity. | O7: SDGs; NDP; NIP 2050; SPLUMA; NSDF; WCSDF 2030; PSP 2025-2030; MSDF; WCIF; PLTF; GPS; State of Development Planning Report and Spatial Performance Report (DEA&DP 2024); RPG-TWG; DEA&DP (Development Planning Report + Spatial Performance Report 2024); CEF; UIDF; MTSF; COGTA; CIF; SDBIP; U-AMP (GIAMA); C-AMP (GIAMA). All planned interventions (projects & programs) to be geo-located & spatially represented, including their expenditure to be expressed spatially.
A8: PP3.2 | B8: PP3 | C8: Public Value and Spatial Justice Innovations | D8: Public value & spatial justice | E8: 8 | F8: Deliver equitable public value while addressing spatial inequities through innovative projects, fostering inclusive planning & development, with a focus on WYPD. | G8: Does the project offer clear evidence of innovations to counter spatial inequalities, to promote inclusive planning and development? | H8: =_xlfn.TEXTJOIN(", ",TRUE(),IF(COUNTIFS(tl_sub,$A8,tl_sdg,1,tl_align,"Primary")>0,"1",""),IF(COUNTIFS(tl_sub,$A8,tl_sdg,2,tl_align,"Primary")>0,"2",""),IF(COUNTIFS(tl_sub,$A8,tl_sdg,3,tl_align,"Primary")>0,"3",""),IF(COUNTIFS(tl_sub,$A8,tl_sdg,4,tl_align,"Primary")>0,"4",""),IF(COUNTIFS(tl_sub,$A8,tl_sdg,5,tl_align,"Primary")>0,"5",""),IF(COUNTIFS(tl_sub,$A8,tl_sdg,6,tl_align,"Primary")>0,"6",""),IF(COUNTIFS(tl_sub,$A8,tl_sdg,7,tl_align,"Primary")>0,"7",""),IF(COUNTIFS(tl_sub,$A8,tl_sdg,8,tl_align,"Primary")>0,"8",""),IF(COUNTIFS(tl_sub,$A8,tl_sdg,9,tl_align,"Primary")>0,"9",""),IF(COUNTIFS(tl_sub,$A8,tl_sdg,10,tl_align,"Primary")>0,"10",""),IF(COUNTIFS(tl_sub,$A8,tl_sdg,11,tl_align,"Primary")>0,"11",""),IF(COUNTIFS(tl_sub,$A8,tl_sdg,12,tl_align,"Primary")>0,"12",""),IF(COUNTIFS(tl_sub,$A8,tl_sdg,13,tl_align,"Primary")>0,"13",""),IF(COUNTIFS(tl_sub,$A8,tl_sdg,14,tl_align,"Primary")>0,"14",""),IF(COUNTIFS(tl_sub,$A8,tl_sdg,15,tl_align,"Primary")>0,"15",""),IF(COUNTIFS(tl_sub,$A8,tl_sdg,16,tl_align,"Primary")>0,"16",""),IF(COUNTIFS(tl_sub,$A8,tl_sdg,17,tl_align,"Primary")>0,"17","")) -> 10, 11 | I8: =_xlfn.TEXTJOIN(", ",TRUE(),IF(COUNTIFS(tl_sub,$A8,tl_sdg,1,tl_align,"Secondary")>0,"1",""),IF(COUNTIFS(tl_sub,$A8,tl_sdg,2,tl_align,"Secondary")>0,"2",""),IF(COUNTIFS(tl_sub,$A8,tl_sdg,3,tl_align,"Secondary")>0,"3",""),IF(COUNTIFS(tl_sub,$A8,tl_sdg,4,tl_align,"Secondary")>0,"4",""),IF(COUNTIFS(tl_sub,$A8,tl_sdg,5,tl_align,"Secondary")>0,"5",""),IF(COUNTIFS(tl_sub,$A8,tl_sdg,6,tl_align,"Secondary")>0,"6",""),IF(COUNTIFS(tl_sub,$A8,tl_sdg,7,tl_align,"Secondary")>0,"7",""),IF(COUNTIFS(tl_sub,$A8,tl_sdg,8,tl_align,"Secondary")>0,"8",""),IF(COUNTIFS(tl_sub,$A8,tl_sdg,9,tl_align,"Secondary")>0,"9",""),IF(COUNTIFS(tl_sub,$A8,tl_sdg,10,tl_align,"Secondary")>0,"10",""),IF(COUNTIFS(tl_sub,$A8,tl_sdg,11,tl_align,"Secondary")>0,"11",""),IF(COUNTIFS(tl_sub,$A8,tl_sdg,12,tl_align,"Secondary")>0,"12",""),IF(COUNTIFS(tl_sub,$A8,tl_sdg,13,tl_align,"Secondary")>0,"13",""),IF(COUNTIFS(tl_sub,$A8,tl_sdg,14,tl_align,"Secondary")>0,"14",""),IF(COUNTIFS(tl_sub,$A8,tl_sdg,15,tl_align,"Secondary")>0,"15",""),IF(COUNTIFS(tl_sub,$A8,tl_sdg,16,tl_align,"Secondary")>0,"16",""),IF(COUNTIFS(tl_sub,$A8,tl_sdg,17,tl_align,"Secondary")>0,"17","")) -> 1, 9, 16 | J8: 10.2, 11.3 | K8: 1.4, 9.1, 16.7 | L8: =COUNTIF(tl_sub,A8) -> 5 | M8: =COUNTIF(il_sub,A8) -> 9 | N8: Promotes equitable public value, inclusive planning and innovative interventions that correct historic and geographic inequalities. | O8: NSDF; WCSDF 2030; MSDF; WCIF (MOIP); PLTF; GPS; DEA&DP (Development Planning Report + Spatial Performance Report 2024); UIDF; UIDG; CIF; CEF; SDBIP.
A9: PP3.3 | B9: PP3 | C9: Partnerships and Localisation Compliance | D9: Partnerships & localisation | E9: 16 | F9: Effective partnerships that demonstrates implementation innovation regarding Risk-Reward sharing; And the use of localised value chains to deliver socio-economic benefits, trust, and stakeholder equity. | G9: Does the project offer clear evidence of desired Partnership models favouring equitable Localised value chain development and risk-sharing? | H9: =_xlfn.TEXTJOIN(", ",TRUE(),IF(COUNTIFS(tl_sub,$A9,tl_sdg,1,tl_align,"Primary")>0,"1",""),IF(COUNTIFS(tl_sub,$A9,tl_sdg,2,tl_align,"Primary")>0,"2",""),IF(COUNTIFS(tl_sub,$A9,tl_sdg,3,tl_align,"Primary")>0,"3",""),IF(COUNTIFS(tl_sub,$A9,tl_sdg,4,tl_align,"Primary")>0,"4",""),IF(COUNTIFS(tl_sub,$A9,tl_sdg,5,tl_align,"Primary")>0,"5",""),IF(COUNTIFS(tl_sub,$A9,tl_sdg,6,tl_align,"Primary")>0,"6",""),IF(COUNTIFS(tl_sub,$A9,tl_sdg,7,tl_align,"Primary")>0,"7",""),IF(COUNTIFS(tl_sub,$A9,tl_sdg,8,tl_align,"Primary")>0,"8",""),IF(COUNTIFS(tl_sub,$A9,tl_sdg,9,tl_align,"Primary")>0,"9",""),IF(COUNTIFS(tl_sub,$A9,tl_sdg,10,tl_align,"Primary")>0,"10",""),IF(COUNTIFS(tl_sub,$A9,tl_sdg,11,tl_align,"Primary")>0,"11",""),IF(COUNTIFS(tl_sub,$A9,tl_sdg,12,tl_align,"Primary")>0,"12",""),IF(COUNTIFS(tl_sub,$A9,tl_sdg,13,tl_align,"Primary")>0,"13",""),IF(COUNTIFS(tl_sub,$A9,tl_sdg,14,tl_align,"Primary")>0,"14",""),IF(COUNTIFS(tl_sub,$A9,tl_sdg,15,tl_align,"Primary")>0,"15",""),IF(COUNTIFS(tl_sub,$A9,tl_sdg,16,tl_align,"Primary")>0,"16",""),IF(COUNTIFS(tl_sub,$A9,tl_sdg,17,tl_align,"Primary")>0,"17","")) -> 17 | I9: =_xlfn.TEXTJOIN(", ",TRUE(),IF(COUNTIFS(tl_sub,$A9,tl_sdg,1,tl_align,"Secondary")>0,"1",""),IF(COUNTIFS(tl_sub,$A9,tl_sdg,2,tl_align,"Secondary")>0,"2",""),IF(COUNTIFS(tl_sub,$A9,tl_sdg,3,tl_align,"Secondary")>0,"3",""),IF(COUNTIFS(tl_sub,$A9,tl_sdg,4,tl_align,"Secondary")>0,"4",""),IF(COUNTIFS(tl_sub,$A9,tl_sdg,5,tl_align,"Secondary")>0,"5",""),IF(COUNTIFS(tl_sub,$A9,tl_sdg,6,tl_align,"Secondary")>0,"6",""),IF(COUNTIFS(tl_sub,$A9,tl_sdg,7,tl_align,"Secondary")>0,"7",""),IF(COUNTIFS(tl_sub,$A9,tl_sdg,8,tl_align,"Secondary")>0,"8",""),IF(COUNTIFS(tl_sub,$A9,tl_sdg,9,tl_align,"Secondary")>0,"9",""),IF(COUNTIFS(tl_sub,$A9,tl_sdg,10,tl_align,"Secondary")>0,"10",""),IF(COUNTIFS(tl_sub,$A9,tl_sdg,11,tl_align,"Secondary")>0,"11",""),IF(COUNTIFS(tl_sub,$A9,tl_sdg,12,tl_align,"Secondary")>0,"12",""),IF(COUNTIFS(tl_sub,$A9,tl_sdg,13,tl_align,"Secondary")>0,"13",""),IF(COUNTIFS(tl_sub,$A9,tl_sdg,14,tl_align,"Secondary")>0,"14",""),IF(COUNTIFS(tl_sub,$A9,tl_sdg,15,tl_align,"Secondary")>0,"15",""),IF(COUNTIFS(tl_sub,$A9,tl_sdg,16,tl_align,"Secondary")>0,"16",""),IF(COUNTIFS(tl_sub,$A9,tl_sdg,17,tl_align,"Secondary")>0,"17","")) -> 8, 10, 12, 16 | J9: 17.16, 17.17 | K9: 8.3, 8.5, 10.2, 12.7, 16.6, 16.7 | L9: =COUNTIF(tl_sub,A9) -> 8 | M9: =COUNTIF(il_sub,A9) -> 11 | N9: Fair risk-and-reward arrangements, stakeholder trust and local value chains support equitable partnerships and locally retained socio-economic benefits. | O9: NT/PFMA; MTEF; NDP; NIP 2050; NLTF; PLTF; NSDF; PSDF; MSDF; PSP 2025-2030; G4J; WCIF; BSA; SABS; UIDF; MTSF; COGTA; CIDB; MSDG; IGM.
A10: PP4.1 | B10: PP4 | C10: Funding, Financing and Budget Governance and Compliance | D10: Funding & budget compliance | E10: 20 | F10: Compliance with provincial, national and international financial and budgetary frameworks to ensure funding sustainability and fiscal discipline. | G10: Does the project offer funding and financing governance frameworks (financial model, etc.) and PFMA and MFMA budgetary compliances; and taking into consideration the IFRS when necessary? | H10: =_xlfn.TEXTJOIN(", ",TRUE(),IF(COUNTIFS(tl_sub,$A10,tl_sdg,1,tl_align,"Primary")>0,"1",""),IF(COUNTIFS(tl_sub,$A10,tl_sdg,2,tl_align,"Primary")>0,"2",""),IF(COUNTIFS(tl_sub,$A10,tl_sdg,3,tl_align,"Primary")>0,"3",""),IF(COUNTIFS(tl_sub,$A10,tl_sdg,4,tl_align,"Primary")>0,"4",""),IF(COUNTIFS(tl_sub,$A10,tl_sdg,5,tl_align,"Primary")>0,"5",""),IF(COUNTIFS(tl_sub,$A10,tl_sdg,6,tl_align,"Primary")>0,"6",""),IF(COUNTIFS(tl_sub,$A10,tl_sdg,7,tl_align,"Primary")>0,"7",""),IF(COUNTIFS(tl_sub,$A10,tl_sdg,8,tl_align,"Primary")>0,"8",""),IF(COUNTIFS(tl_sub,$A10,tl_sdg,9,tl_align,"Primary")>0,"9",""),IF(COUNTIFS(tl_sub,$A10,tl_sdg,10,tl_align,"Primary")>0,"10",""),IF(COUNTIFS(tl_sub,$A10,tl_sdg,11,tl_align,"Primary")>0,"11",""),IF(COUNTIFS(tl_sub,$A10,tl_sdg,12,tl_align,"Primary")>0,"12",""),IF(COUNTIFS(tl_sub,$A10,tl_sdg,13,tl_align,"Primary")>0,"13",""),IF(COUNTIFS(tl_sub,$A10,tl_sdg,14,tl_align,"Primary")>0,"14",""),IF(COUNTIFS(tl_sub,$A10,tl_sdg,15,tl_align,"Primary")>0,"15",""),IF(COUNTIFS(tl_sub,$A10,tl_sdg,16,tl_align,"Primary")>0,"16",""),IF(COUNTIFS(tl_sub,$A10,tl_sdg,17,tl_align,"Primary")>0,"17","")) -> 16 | I10: =_xlfn.TEXTJOIN(", ",TRUE(),IF(COUNTIFS(tl_sub,$A10,tl_sdg,1,tl_align,"Secondary")>0,"1",""),IF(COUNTIFS(tl_sub,$A10,tl_sdg,2,tl_align,"Secondary")>0,"2",""),IF(COUNTIFS(tl_sub,$A10,tl_sdg,3,tl_align,"Secondary")>0,"3",""),IF(COUNTIFS(tl_sub,$A10,tl_sdg,4,tl_align,"Secondary")>0,"4",""),IF(COUNTIFS(tl_sub,$A10,tl_sdg,5,tl_align,"Secondary")>0,"5",""),IF(COUNTIFS(tl_sub,$A10,tl_sdg,6,tl_align,"Secondary")>0,"6",""),IF(COUNTIFS(tl_sub,$A10,tl_sdg,7,tl_align,"Secondary")>0,"7",""),IF(COUNTIFS(tl_sub,$A10,tl_sdg,8,tl_align,"Secondary")>0,"8",""),IF(COUNTIFS(tl_sub,$A10,tl_sdg,9,tl_align,"Secondary")>0,"9",""),IF(COUNTIFS(tl_sub,$A10,tl_sdg,10,tl_align,"Secondary")>0,"10",""),IF(COUNTIFS(tl_sub,$A10,tl_sdg,11,tl_align,"Secondary")>0,"11",""),IF(COUNTIFS(tl_sub,$A10,tl_sdg,12,tl_align,"Secondary")>0,"12",""),IF(COUNTIFS(tl_sub,$A10,tl_sdg,13,tl_align,"Secondary")>0,"13",""),IF(COUNTIFS(tl_sub,$A10,tl_sdg,14,tl_align,"Secondary")>0,"14",""),IF(COUNTIFS(tl_sub,$A10,tl_sdg,15,tl_align,"Secondary")>0,"15",""),IF(COUNTIFS(tl_sub,$A10,tl_sdg,16,tl_align,"Secondary")>0,"16",""),IF(COUNTIFS(tl_sub,$A10,tl_sdg,17,tl_align,"Secondary")>0,"17","")) -> 17 | J10: 16.6 | K10: 17.1, 17.3, 17.4, 17.14 | L10: =COUNTIF(tl_sub,A10) -> 5 | M10: =COUNTIF(il_sub,A10) -> 8 | N10: Compliance with financial and budget frameworks strengthens fiscal discipline, accountability, institutional effectiveness and sustainable infrastructure funding. | O10: NT/PFMA; MTEF; NDP; NIP 2050; PT; G4J; WCIF; MFMA; MTSF; CEF; UIDG; COGTA; LTFP; CIP; IGM; SDIP; C-AMP (GIAMA); U-AMP (GIAMA).
A11: PP4.2 | B11: PP4 | C11: Socio-economic Compliance | D11: Socio-economic compliance | E11: 8 | F11: Adherence to socio-economic planning frameworks and policies, aligning infrastructure projects with growth development priorities and policy objectives as part of effective governance and transversal planning (also take into consideration decommissioning and repurposing). | G11: Does the project offer clear evidence of alignment of socio-economic growth and development priorities required by transversal planning prescripts? | H11: =_xlfn.TEXTJOIN(", ",TRUE(),IF(COUNTIFS(tl_sub,$A11,tl_sdg,1,tl_align,"Primary")>0,"1",""),IF(COUNTIFS(tl_sub,$A11,tl_sdg,2,tl_align,"Primary")>0,"2",""),IF(COUNTIFS(tl_sub,$A11,tl_sdg,3,tl_align,"Primary")>0,"3",""),IF(COUNTIFS(tl_sub,$A11,tl_sdg,4,tl_align,"Primary")>0,"4",""),IF(COUNTIFS(tl_sub,$A11,tl_sdg,5,tl_align,"Primary")>0,"5",""),IF(COUNTIFS(tl_sub,$A11,tl_sdg,6,tl_align,"Primary")>0,"6",""),IF(COUNTIFS(tl_sub,$A11,tl_sdg,7,tl_align,"Primary")>0,"7",""),IF(COUNTIFS(tl_sub,$A11,tl_sdg,8,tl_align,"Primary")>0,"8",""),IF(COUNTIFS(tl_sub,$A11,tl_sdg,9,tl_align,"Primary")>0,"9",""),IF(COUNTIFS(tl_sub,$A11,tl_sdg,10,tl_align,"Primary")>0,"10",""),IF(COUNTIFS(tl_sub,$A11,tl_sdg,11,tl_align,"Primary")>0,"11",""),IF(COUNTIFS(tl_sub,$A11,tl_sdg,12,tl_align,"Primary")>0,"12",""),IF(COUNTIFS(tl_sub,$A11,tl_sdg,13,tl_align,"Primary")>0,"13",""),IF(COUNTIFS(tl_sub,$A11,tl_sdg,14,tl_align,"Primary")>0,"14",""),IF(COUNTIFS(tl_sub,$A11,tl_sdg,15,tl_align,"Primary")>0,"15",""),IF(COUNTIFS(tl_sub,$A11,tl_sdg,16,tl_align,"Primary")>0,"16",""),IF(COUNTIFS(tl_sub,$A11,tl_sdg,17,tl_align,"Primary")>0,"17","")) -> 16 | I11: =_xlfn.TEXTJOIN(", ",TRUE(),IF(COUNTIFS(tl_sub,$A11,tl_sdg,1,tl_align,"Secondary")>0,"1",""),IF(COUNTIFS(tl_sub,$A11,tl_sdg,2,tl_align,"Secondary")>0,"2",""),IF(COUNTIFS(tl_sub,$A11,tl_sdg,3,tl_align,"Secondary")>0,"3",""),IF(COUNTIFS(tl_sub,$A11,tl_sdg,4,tl_align,"Secondary")>0,"4",""),IF(COUNTIFS(tl_sub,$A11,tl_sdg,5,tl_align,"Secondary")>0,"5",""),IF(COUNTIFS(tl_sub,$A11,tl_sdg,6,tl_align,"Secondary")>0,"6",""),IF(COUNTIFS(tl_sub,$A11,tl_sdg,7,tl_align,"Secondary")>0,"7",""),IF(COUNTIFS(tl_sub,$A11,tl_sdg,8,tl_align,"Secondary")>0,"8",""),IF(COUNTIFS(tl_sub,$A11,tl_sdg,9,tl_align,"Secondary")>0,"9",""),IF(COUNTIFS(tl_sub,$A11,tl_sdg,10,tl_align,"Secondary")>0,"10",""),IF(COUNTIFS(tl_sub,$A11,tl_sdg,11,tl_align,"Secondary")>0,"11",""),IF(COUNTIFS(tl_sub,$A11,tl_sdg,12,tl_align,"Secondary")>0,"12",""),IF(COUNTIFS(tl_sub,$A11,tl_sdg,13,tl_align,"Secondary")>0,"13",""),IF(COUNTIFS(tl_sub,$A11,tl_sdg,14,tl_align,"Secondary")>0,"14",""),IF(COUNTIFS(tl_sub,$A11,tl_sdg,15,tl_align,"Secondary")>0,"15",""),IF(COUNTIFS(tl_sub,$A11,tl_sdg,16,tl_align,"Secondary")>0,"16",""),IF(COUNTIFS(tl_sub,$A11,tl_sdg,17,tl_align,"Secondary")>0,"17","")) -> 8, 10, 11, 17 | J11: 16.6, 16.7 | K11: 8.3, 10.2, 11.a, 17.14 | L11: =COUNTIF(tl_sub,A11) -> 6 | M11: =COUNTIF(il_sub,A11) -> 8 | N11: Alignment with socio-economic policies and development priorities enables accountable governance, coordinated planning and inclusive growth. | O11: NSDF; WCSDF 2030; MSDF; WCIF; PLTF; MOIP; G4J; UID; MTSF; COGTA; CIDB; LTFP; CIF; CEF; SDBIP.
D12: Total | E12: =SUM(E2:E11) -> 100 | L12: =SUM(L2:L11) -> 66 | M12: =SUM(M2:M11) -> 103

Sheet Target links
A1: Link ID | B1: Principle | C1: Sub-principle | D1: SDG | E1: SDG name | F1: Target | G1: Target short name | H1: Target text (UNSD) | I1: Alignment | J1: Department label | K1: Indicators
A2: PP1.1|9.1 | B2: PP1 | C2: PP1.1 | D2: 9 | E2: Industry, Innovation and Infrastructure | F2: 9.1 | G2: Quality, resilient infrastructure | H2: Develop quality, reliable, sustainable and resilient infrastructure, including regional and transborder infrastructure, to support economic development and human well-being, with a focus on affordable and equitable access for all | I2: Primary | K2: =COUNTIF('Indicator links'!$A$2:$A$500,A2) -> 2
A3: PP1.1|9.4 | B3: PP1 | C3: PP1.1 | D3: 9 | E3: Industry, Innovation and Infrastructure | F3: 9.4 | G3: Sustainable, retrofitted infrastructure | H3: By 2030, upgrade infrastructure and retrofit industries to make them sustainable, with increased resource-use efficiency and greater adoption of clean and environmentally sound technologies and industrial processes, with all countries taking action in accordance with their respective capabilities | I3: Primary | K3: =COUNTIF('Indicator links'!$A$2:$A$500,A3) -> 1
A4: PP1.1|9.5 | B4: PP1 | C4: PP1.1 | D4: 9 | E4: Industry, Innovation and Infrastructure | F4: 9.5 | G4: Research and technological capability | H4: Enhance scientific research, upgrade the technological capabilities of industrial sectors in all countries, in particular developing countries, including, by 2030, encouraging innovation and substantially increasing the number of research and development workers per 1 million people and public and private research and development spending | I4: Primary | K4: =COUNTIF('Indicator links'!$A$2:$A$500,A4) -> 2
A5: PP1.1|8.2 | B5: PP1 | C5: PP1.1 | D5: 8 | E5: Decent Work and Economic Growth | F5: 8.2 | G5: Productivity through innovation | H5: Achieve higher levels of economic productivity through diversification, technological upgrading and innovation, including through a focus on high-value added and labour-intensive sectors | I5: Secondary | J5: innovation-led productivity | K5: =COUNTIF('Indicator links'!$A$2:$A$500,A5) -> 1
A6: PP1.1|11.3 | B6: PP1 | C6: PP1.1 | D6: 11 | E6: Sustainable Cities and Communities | F6: 11.3 | G6: Inclusive, integrated urban planning | H6: By 2030, enhance inclusive and sustainable urbanization and capacity for participatory, integrated and sustainable human settlement planning and management in all countries | I6: Secondary | J6: integrated urban planning | K6: =COUNTIF('Indicator links'!$A$2:$A$500,A6) -> 2
A7: PP1.1|12.2 | B7: PP1 | C7: PP1.1 | D7: 12 | E7: Responsible Consumption and Production | F7: 12.2 | G7: Sustainable use of natural resources | H7: By 2030, achieve the sustainable management and efficient use of natural resources | I7: Secondary | J7: efficient use of natural resources | K7: =COUNTIF('Indicator links'!$A$2:$A$500,A7) -> 2
A8: PP1.2|9.5 | B8: PP1 | C8: PP1.2 | D8: 9 | E8: Industry, Innovation and Infrastructure | F8: 9.5 | G8: Research and technological capability | H8: Enhance scientific research, upgrade the technological capabilities of industrial sectors in all countries, in particular developing countries, including, by 2030, encouraging innovation and substantially increasing the number of research and development workers per 1 million people and public and private research and development spending | I8: Primary | K8: =COUNTIF('Indicator links'!$A$2:$A$500,A8) -> 2
A9: PP1.2|9.c | B9: PP1 | C9: PP1.2 | D9: 9 | E9: Industry, Innovation and Infrastructure | F9: 9.c | G9: Access to ICT and the internet | H9: Significantly increase access to information and communications technology and strive to provide universal and affordable access to the Internet in least developed countries by 2020 | I9: Primary | K9: =COUNTIF('Indicator links'!$A$2:$A$500,A9) -> 1
A10: PP1.2|8.2 | B10: PP1 | C10: PP1.2 | D10: 8 | E10: Decent Work and Economic Growth | F10: 8.2 | G10: Productivity through innovation | H10: Achieve higher levels of economic productivity through diversification, technological upgrading and innovation, including through a focus on high-value added and labour-intensive sectors | I10: Secondary | J10: technological upgrading | K10: =COUNTIF('Indicator links'!$A$2:$A$500,A10) -> 1
A11: PP1.2|16.6 | B11: PP1 | C11: PP1.2 | D11: 16 | E11: Peace, Justice and Strong Institutions | F11: 16.6 | G11: Effective, accountable institutions | H11: Develop effective, accountable and transparent institutions at all levels | I11: Secondary | J11: effective institutions | K11: =COUNTIF('Indicator links'!$A$2:$A$500,A11) -> 2
A12: PP1.2|16.10 | B12: PP1 | C12: PP1.2 | D12: 16 | E12: Peace, Justice and Strong Institutions | F12: 16.10 | G12: Public access to information | H12: Ensure public access to information and protect fundamental freedoms, in accordance with national legislation and international agreements | I12: Secondary | J12: access to information | K12: =COUNTIF('Indicator links'!$A$2:$A$500,A12) -> 2
A13: PP1.2|17.8 | B13: PP1 | C13: PP1.2 | D13: 17 | E13: Partnerships for the Goals | F13: 17.8 | G13: Enabling technology and ICT | H13: Fully operationalize the technology bank and science, technology and innovation capacity-building mechanism for least developed countries by 2017 and enhance the use of enabling technology, in particular information and communications technology | I13: Secondary | J13: enabling technology | K13: =COUNTIF('Indicator links'!$A$2:$A$500,A13) -> 1
A14: PP2.1|9.1 | B14: PP2 | C14: PP2.1 | D14: 9 | E14: Industry, Innovation and Infrastructure | F14: 9.1 | G14: Quality, resilient infrastructure | H14: Develop quality, reliable, sustainable and resilient infrastructure, including regional and transborder infrastructure, to support economic development and human well-being, with a focus on affordable and equitable access for all | I14: Primary | K14: =COUNTIF('Indicator links'!$A$2:$A$500,A14) -> 2
A15: PP2.1|13.1 | B15: PP2 | C15: PP2.1 | D15: 13 | E15: Climate Action | F15: 13.1 | G15: Climate resilience and adaptive capacity | H15: Strengthen resilience and adaptive capacity to climate-related hazards and natural disasters in all countries | I15: Primary | K15: =COUNTIF('Indicator links'!$A$2:$A$500,A15) -> 3
A16: PP2.1|13.2 | B16: PP2 | C16: PP2.1 | D16: 13 | E16: Climate Action | F16: 13.2 | G16: Climate measures in plans and policies | H16: Integrate climate change measures into national policies, strategies and planning | I16: Primary | K16: =COUNTIF('Indicator links'!$A$2:$A$500,A16) -> 2
A17: PP2.1|6.4 | B17: PP2 | C17: PP2.1 | D17: 6 | E17: Clean Water and Sanitation | F17: 6.4 | G17: Water-use efficiency | H17: By 2030, substantially increase water-use efficiency across all sectors and ensure sustainable withdrawals and supply of freshwater to address water scarcity and substantially reduce the number of people suffering from water scarcity | I17: Secondary | J17: water efficiency and integrated management | K17: =COUNTIF('Indicator links'!$A$2:$A$500,A17) -> 2
A18: PP2.1|6.5 | B18: PP2 | C18: PP2.1 | D18: 6 | E18: Clean Water and Sanitation | F18: 6.5 | G18: Integrated water resources management | H18: By 2030, implement integrated water resources management at all levels, including through transboundary cooperation as appropriate | I18: Secondary | J18: water efficiency and integrated management | K18: =COUNTIF('Indicator links'!$A$2:$A$500,A18) -> 2
A19: PP2.1|7.2 | B19: PP2 | C19: PP2.1 | D19: 7 | E19: Affordable and Clean Energy | F19: 7.2 | G19: Renewable energy share | H19: By 2030, increase substantially the share of renewable energy in the global energy mix | I19: Secondary | J19: renewable energy and energy efficiency | K19: =COUNTIF('Indicator links'!$A$2:$A$500,A19) -> 1
A20: PP2.1|7.3 | B20: PP2 | C20: PP2.1 | D20: 7 | E20: Affordable and Clean Energy | F20: 7.3 | G20: Energy efficiency | H20: By 2030, double the global rate of improvement in energy efficiency | I20: Secondary | J20: renewable energy and energy efficiency | K20: =COUNTIF('Indicator links'!$A$2:$A$500,A20) -> 1
A21: PP2.1|11.5 | B21: PP2 | C21: PP2.1 | D21: 11 | E21: Sustainable Cities and Communities | F21: 11.5 | G21: Reduced disaster losses | H21: By 2030, significantly reduce the number of deaths and the number of people affected and substantially decrease the direct economic losses relative to global gross domestic product caused by disasters, including water-related disasters, with a focus on protecting the poor and people in vulnerable situations | I21: Secondary | J21: disaster resilience | K21: =COUNTIF('Indicator links'!$A$2:$A$500,A21) -> 3
A22: PP2.1|11.b | B22: PP2 | C22: PP2.1 | D22: 11 | E22: Sustainable Cities and Communities | F22: 11.b | G22: Integrated climate and disaster-risk policies | H22: By 2020, substantially increase the number of cities and human settlements adopting and implementing integrated policies and plans towards inclusion, resource efficiency, mitigation and adaptation to climate change, resilience to disasters, and develop and implement, in line with the Sendai Framework for Disaster Risk Reduction 2015–2030, holistic disaster risk management at all levels | I22: Secondary | J22: disaster resilience | K22: =COUNTIF('Indicator links'!$A$2:$A$500,A22) -> 2
A23: PP2.1|12.2 | B23: PP2 | C23: PP2.1 | D23: 12 | E23: Responsible Consumption and Production | F23: 12.2 | G23: Sustainable use of natural resources | H23: By 2030, achieve the sustainable management and efficient use of natural resources | I23: Secondary | J23: sustainable resource use | K23: =COUNTIF('Indicator links'!$A$2:$A$500,A23) -> 2
A24: PP2.2|11.3 | B24: PP2 | C24: PP2.2 | D24: 11 | E24: Sustainable Cities and Communities | F24: 11.3 | G24: Inclusive, integrated urban planning | H24: By 2030, enhance inclusive and sustainable urbanization and capacity for participatory, integrated and sustainable human settlement planning and management in all countries | I24: Primary | K24: =COUNTIF('Indicator links'!$A$2:$A$500,A24) -> 2
A25: PP2.2|11.a | B25: PP2 | C25: PP2.2 | D25: 11 | E25: Sustainable Cities and Communities | F25: 11.a | G25: Urban–rural planning links | H25: Support positive economic, social and environmental links between urban, peri-urban and rural areas by strengthening national and regional development planning | I25: Primary | K25: =COUNTIF('Indicator links'!$A$2:$A$500,A25) -> 1
A26: PP2.2|9.1 | B26: PP2 | C26: PP2.2 | D26: 9 | E26: Industry, Innovation and Infrastructure | F26: 9.1 | G26: Quality, resilient infrastructure | H26: Develop quality, reliable, sustainable and resilient infrastructure, including regional and transborder infrastructure, to support economic development and human well-being, with a focus on affordable and equitable access for all | I26: Secondary | J26: sustainable infrastructure | K26: =COUNTIF('Indicator links'!$A$2:$A$500,A26) -> 2
A27: PP2.2|13.2 | B27: PP2 | C27: PP2.2 | D27: 13 | E27: Climate Action | F27: 13.2 | G27: Climate measures in plans and policies | H27: Integrate climate change measures into national policies, strategies and planning | I27: Secondary | J27: climate integration | K27: =COUNTIF('Indicator links'!$A$2:$A$500,A27) -> 2
A28: PP2.2|17.14 | B28: PP2 | C28: PP2.2 | D28: 17 | E28: Partnerships for the Goals | F28: 17.14 | G28: Policy coherence | H28: Enhance policy coherence for sustainable development | I28: Secondary | J28: policy coherence | K28: =COUNTIF('Indicator links'!$A$2:$A$500,A28) -> 1
A29: PP2.2|17.16 | B29: PP2 | C29: PP2.2 | D29: 17 | E29: Partnerships for the Goals | F29: 17.16 | G29: Multi-stakeholder partnerships | H29: Enhance the Global Partnership for Sustainable Development, complemented by multi-stakeholder partnerships that mobilize and share knowledge, expertise, technology and financial resources, to support the achievement of the Sustainable Development Goals in all countries, in particular developing countries | I29: Secondary | J29: partnerships | K29: =COUNTIF('Indicator links'!$A$2:$A$500,A29) -> 1
A30: PP2.2|17.17 | B30: PP2 | C30: PP2.2 | D30: 17 | E30: Partnerships for the Goals | F30: 17.17 | G30: Public, public-private and civil society partnerships | H30: Encourage and promote effective public, public-private and civil society partnerships, building on the experience and resourcing strategies of partnerships | I30: Secondary | J30: partnerships | K30: =COUNTIF('Indicator links'!$A$2:$A$500,A30) -> 1
A31: PP2.3|12.2 | B31: PP2 | C31: PP2.3 | D31: 12 | E31: Responsible Consumption and Production | F31: 12.2 | G31: Sustainable use of natural resources | H31: By 2030, achieve the sustainable management and efficient use of natural resources | I31: Primary | K31: =COUNTIF('Indicator links'!$A$2:$A$500,A31) -> 2
A32: PP2.3|12.7 | B32: PP2 | C32: PP2.3 | D32: 12 | E32: Responsible Consumption and Production | F32: 12.7 | G32: Sustainable public procurement | H32: Promote public procurement practices that are sustainable, in accordance with national policies and priorities | I32: Primary | K32: =COUNTIF('Indicator links'!$A$2:$A$500,A32) -> 1
A33: PP2.3|8.3 | B33: PP2 | C33: PP2.3 | D33: 8 | E33: Decent Work and Economic Growth | F33: 8.3 | G33: Enterprise and small-business growth | H33: Promote development-oriented policies that support productive activities, decent job creation, entrepreneurship, creativity and innovation, and encourage the formalization and growth of micro-, small- and medium-sized enterprises, including through access to financial services | I33: Secondary | J33: local enterprise development | K33: =COUNTIF('Indicator links'!$A$2:$A$500,A33) -> 1
A34: PP2.3|9.4 | B34: PP2 | C34: PP2.3 | D34: 9 | E34: Industry, Innovation and Infrastructure | F34: 9.4 | G34: Sustainable, retrofitted infrastructure | H34: By 2030, upgrade infrastructure and retrofit industries to make them sustainable, with increased resource-use efficiency and greater adoption of clean and environmentally sound technologies and industrial processes, with all countries taking action in accordance with their respective capabilities | I34: Secondary | J34: resource-efficient industry | K34: =COUNTIF('Indicator links'!$A$2:$A$500,A34) -> 1
A35: PP2.3|11.6 | B35: PP2 | C35: PP2.3 | D35: 11 | E35: Sustainable Cities and Communities | F35: 11.6 | G35: Lower urban environmental impact | H35: By 2030, reduce the adverse per capita environmental impact of cities, including by paying special attention to air quality and municipal and other waste management | I35: Secondary | J35: lower urban environmental impact | K35: =COUNTIF('Indicator links'!$A$2:$A$500,A35) -> 2
A36: PP2.3|13.2 | B36: PP2 | C36: PP2.3 | D36: 13 | E36: Climate Action | F36: 13.2 | G36: Climate measures in plans and policies | H36: Integrate climate change measures into national policies, strategies and planning | I36: Secondary | J36: climate considerations | K36: =COUNTIF('Indicator links'!$A$2:$A$500,A36) -> 2
A37: PP3.1|11.1 | B37: PP3 | C37: PP3.1 | D37: 11 | E37: Sustainable Cities and Communities | F37: 11.1 | G37: Adequate housing and basic services | H37: By 2030, ensure access for all to adequate, safe and affordable housing and basic services and upgrade slums | I37: Primary | K37: =COUNTIF('Indicator links'!$A$2:$A$500,A37) -> 1
